Traceback (most recent call last):
  File "/home/thormakai/anaconda3/envs/myenv/lib/python3.8/site-packages/jupyter_cache/executors/utils.py", line 51, in single_nb_execution
    executenb(
  File "/home/thormakai/anaconda3/envs/myenv/lib/python3.8/site-packages/nbclient/client.py", line 1112, in execute
    return NotebookClient(nb=nb, resources=resources, km=km, **kwargs).execute()
  File "/home/thormakai/anaconda3/envs/myenv/lib/python3.8/site-packages/nbclient/util.py", line 74, in wrapped
    return just_run(coro(*args, **kwargs))
  File "/home/thormakai/anaconda3/envs/myenv/lib/python3.8/site-packages/nbclient/util.py", line 53, in just_run
    return loop.run_until_complete(coro)
  File "/home/thormakai/anaconda3/envs/myenv/lib/python3.8/asyncio/base_events.py", line 616, in run_until_complete
    return future.result()
  File "/home/thormakai/anaconda3/envs/myenv/lib/python3.8/site-packages/nbclient/client.py", line 553, in async_execute
    await self.async_execute_cell(
  File "/home/thormakai/anaconda3/envs/myenv/lib/python3.8/site-packages/nbclient/client.py", line 857, in async_execute_cell
    self._check_raise_for_error(cell, exec_reply)
  File "/home/thormakai/anaconda3/envs/myenv/lib/python3.8/site-packages/nbclient/client.py", line 760, in _check_raise_for_error
    raise CellExecutionError.from_cell_and_msg(cell, exec_reply_content)
nbclient.exceptions.CellExecutionError: An error occurred while executing the following cell:
------------------
this_picture = PILImage.open("resources/germ-1.jpeg")
output = io.BytesIO()
this_picture.thumbnail((800, 1200))
this_picture.save(output, format='PNG')
encoded_string = base64.b64encode(output.getvalue()).decode()

html = '<img src="data:image/png;base64,{}"/>'.format(encoded_string)
md(html)
------------------

[0;31m---------------------------------------------------------------------------[0m
[0;31mFileNotFoundError[0m                         Traceback (most recent call last)
[0;32m/tmp/ipykernel_25845/2960544121.py[0m in [0;36m<module>[0;34m[0m
[0;32m----> 1[0;31m [0mthis_picture[0m [0;34m=[0m [0mPILImage[0m[0;34m.[0m[0mopen[0m[0;34m([0m[0;34m"resources/germ-1.jpeg"[0m[0;34m)[0m[0;34m[0m[0;34m[0m[0m
[0m[1;32m      2[0m [0moutput[0m [0;34m=[0m [0mio[0m[0;34m.[0m[0mBytesIO[0m[0;34m([0m[0;34m)[0m[0;34m[0m[0;34m[0m[0m
[1;32m      3[0m [0mthis_picture[0m[0;34m.[0m[0mthumbnail[0m[0;34m([0m[0;34m([0m[0;36m800[0m[0;34m,[0m [0;36m1200[0m[0;34m)[0m[0;34m)[0m[0;34m[0m[0;34m[0m[0m
[1;32m      4[0m [0mthis_picture[0m[0;34m.[0m[0msave[0m[0;34m([0m[0moutput[0m[0;34m,[0m [0mformat[0m[0;34m=[0m[0;34m'PNG'[0m[0;34m)[0m[0;34m[0m[0;34m[0m[0m
[1;32m      5[0m [0mencoded_string[0m [0;34m=[0m [0mbase64[0m[0;34m.[0m[0mb64encode[0m[0;34m([0m[0moutput[0m[0;34m.[0m[0mgetvalue[0m[0;34m([0m[0;34m)[0m[0;34m)[0m[0;34m.[0m[0mdecode[0m[0;34m([0m[0;34m)[0m[0;34m[0m[0;34m[0m[0m

[0;32m~/anaconda3/envs/myenv/lib/python3.8/site-packages/PIL/Image.py[0m in [0;36mopen[0;34m(fp, mode, formats)[0m
[1;32m   2973[0m [0;34m[0m[0m
[1;32m   2974[0m     [0;32mif[0m [0mfilename[0m[0;34m:[0m[0;34m[0m[0;34m[0m[0m
[0;32m-> 2975[0;31m         [0mfp[0m [0;34m=[0m [0mbuiltins[0m[0;34m.[0m[0mopen[0m[0;34m([0m[0mfilename[0m[0;34m,[0m [0;34m"rb"[0m[0;34m)[0m[0;34m[0m[0;34m[0m[0m
[0m[1;32m   2976[0m         [0mexclusive_fp[0m [0;34m=[0m [0;32mTrue[0m[0;34m[0m[0;34m[0m[0m
[1;32m   2977[0m [0;34m[0m[0m

[0;31mFileNotFoundError[0m: [Errno 2] No such file or directory: 'resources/germ-1.jpeg'
FileNotFoundError: [Errno 2] No such file or directory: 'resources/germ-1.jpeg'

